nohup: ignoring input
INFO:     Started server process [248061]
INFO:     Waiting for application startup.
INFO:     Application startup complete.
INFO:     Uvicorn running on http://0.0.0.0:8000 (Press CTRL+C to quit)
INFO:     127.0.0.1:43836 - "GET /health HTTP/1.1" 200 OK
INFO:     127.0.0.1:51526 - "GET / HTTP/1.1" 200 OK
ERROR:    Exception in ASGI application
Traceback (most recent call last):
  File "/home/haru/Projects/Major project/compliance auditor/backend/venv/lib/python3.10/site-packages/starlette/middleware/exceptions.py", line 68, in __call__
    await self.app(scope, receive, sender)
  File "/home/haru/Projects/Major project/compliance auditor/backend/venv/lib/python3.10/site-packages/fastapi/middleware/asyncexitstack.py", line 20, in __call__
    raise e
  File "/home/haru/Projects/Major project/compliance auditor/backend/venv/lib/python3.10/site-packages/fastapi/middleware/asyncexitstack.py", line 17, in __call__
    await self.app(scope, receive, send)
  File "/home/haru/Projects/Major project/compliance auditor/backend/venv/lib/python3.10/site-packages/starlette/routing.py", line 747, in __call__
    await self.default(scope, receive, send)
  File "/home/haru/Projects/Major project/compliance auditor/backend/venv/lib/python3.10/site-packages/starlette/routing.py", line 635, in not_found
    raise HTTPException(status_code=404)
starlette.exceptions.HTTPException

During handling of the above exception, another exception occurred:

Traceback (most recent call last):
  File "/home/haru/Projects/Major project/compliance auditor/backend/venv/lib/python3.10/site-packages/starlette/middleware/errors.py", line 162, in __call__
    await self.app(scope, receive, _send)
  File "/home/haru/Projects/Major project/compliance auditor/backend/venv/lib/python3.10/site-packages/starlette/middleware/cors.py", line 83, in __call__
    await self.app(scope, receive, send)
  File "/home/haru/Projects/Major project/compliance auditor/backend/venv/lib/python3.10/site-packages/starlette/middleware/exceptions.py", line 91, in __call__
    await response(scope, receive, sender)
TypeError: 'dict' object is not callable

During handling of the above exception, another exception occurred:

Traceback (most recent call last):
  File "/home/haru/Projects/Major project/compliance auditor/backend/venv/lib/python3.10/site-packages/uvicorn/protocols/http/h11_impl.py", line 408, in run_asgi
    result = await app(  # type: ignore[func-returns-value]
  File "/home/haru/Projects/Major project/compliance auditor/backend/venv/lib/python3.10/site-packages/uvicorn/middleware/proxy_headers.py", line 84, in __call__
    return await self.app(scope, receive, send)
  File "/home/haru/Projects/Major project/compliance auditor/backend/venv/lib/python3.10/site-packages/fastapi/applications.py", line 1106, in __call__
    await super().__call__(scope, receive, send)
  File "/home/haru/Projects/Major project/compliance auditor/backend/venv/lib/python3.10/site-packages/starlette/applications.py", line 122, in __call__
    await self.middleware_stack(scope, receive, send)
  File "/home/haru/Projects/Major project/compliance auditor/backend/venv/lib/python3.10/site-packages/starlette/middleware/errors.py", line 179, in __call__
    await response(scope, receive, send)
TypeError: 'dict' object is not callable
INFO:     None:0 - "GET /favicon.ico HTTP/1.1" 500 Internal Server Error
ERROR:    Exception in ASGI application
Traceback (most recent call last):
  File "/home/haru/Projects/Major project/compliance auditor/backend/venv/lib/python3.10/site-packages/starlette/middleware/exceptions.py", line 68, in __call__
    await self.app(scope, receive, sender)
  File "/home/haru/Projects/Major project/compliance auditor/backend/venv/lib/python3.10/site-packages/fastapi/middleware/asyncexitstack.py", line 20, in __call__
    raise e
  File "/home/haru/Projects/Major project/compliance auditor/backend/venv/lib/python3.10/site-packages/fastapi/middleware/asyncexitstack.py", line 17, in __call__
    await self.app(scope, receive, send)
  File "/home/haru/Projects/Major project/compliance auditor/backend/venv/lib/python3.10/site-packages/starlette/routing.py", line 747, in __call__
    await self.default(scope, receive, send)
  File "/home/haru/Projects/Major project/compliance auditor/backend/venv/lib/python3.10/site-packages/starlette/routing.py", line 635, in not_found
    raise HTTPException(status_code=404)
starlette.exceptions.HTTPException

During handling of the above exception, another exception occurred:

Traceback (most recent call last):
  File "/home/haru/Projects/Major project/compliance auditor/backend/venv/lib/python3.10/site-packages/starlette/middleware/errors.py", line 162, in __call__
    await self.app(scope, receive, _send)
  File "/home/haru/Projects/Major project/compliance auditor/backend/venv/lib/python3.10/site-packages/starlette/middleware/cors.py", line 83, in __call__
    await self.app(scope, receive, send)
  File "/home/haru/Projects/Major project/compliance auditor/backend/venv/lib/python3.10/site-packages/starlette/middleware/exceptions.py", line 91, in __call__
    await response(scope, receive, sender)
TypeError: 'dict' object is not callable

During handling of the above exception, another exception occurred:

Traceback (most recent call last):
  File "/home/haru/Projects/Major project/compliance auditor/backend/venv/lib/python3.10/site-packages/uvicorn/protocols/http/h11_impl.py", line 408, in run_asgi
    result = await app(  # type: ignore[func-returns-value]
  File "/home/haru/Projects/Major project/compliance auditor/backend/venv/lib/python3.10/site-packages/uvicorn/middleware/proxy_headers.py", line 84, in __call__
    return await self.app(scope, receive, send)
  File "/home/haru/Projects/Major project/compliance auditor/backend/venv/lib/python3.10/site-packages/fastapi/applications.py", line 1106, in __call__
    await super().__call__(scope, receive, send)
  File "/home/haru/Projects/Major project/compliance auditor/backend/venv/lib/python3.10/site-packages/starlette/applications.py", line 122, in __call__
    await self.middleware_stack(scope, receive, send)
  File "/home/haru/Projects/Major project/compliance auditor/backend/venv/lib/python3.10/site-packages/starlette/middleware/errors.py", line 179, in __call__
    await response(scope, receive, send)
TypeError: 'dict' object is not callable
INFO:     None:0 - "GET /logo192.png HTTP/1.1" 500 Internal Server Error
INFO:     127.0.0.1:47332 - "GET /health HTTP/1.1" 200 OK
INFO:     127.0.0.1:47334 - "GET /health HTTP/1.1" 200 OK
INFO:utils.git_utils:Starting to clone repository: https://github.com/octocat/Hello-World
INFO:utils.git_utils:Cloning to: /tmp/tmp_lcpcskr/repo
INFO:utils.git_utils:Repository cloned successfully to: /tmp/tmp_lcpcskr/repo
INFO:     127.0.0.1:47878 - "POST /git-scan-detailed HTTP/1.1" 200 OK
INFO:utils.git_utils:Starting to clone repository: https://github.com/octocat/Hello-World
INFO:utils.git_utils:Cloning to: /tmp/tmpyhaymqum/repo
INFO:utils.git_utils:Repository cloned successfully to: /tmp/tmpyhaymqum/repo
INFO:     127.0.0.1:47894 - "POST /git-scan-detailed HTTP/1.1" 200 OK
INFO:     127.0.0.1:54896 - "GET /health HTTP/1.1" 200 OK
INFO:     127.0.0.1:54912 - "GET /health HTTP/1.1" 200 OK
ERROR:    Exception in ASGI application
Traceback (most recent call last):
  File "/home/haru/Projects/Major project/compliance auditor/backend/venv/lib/python3.10/site-packages/starlette/middleware/exceptions.py", line 68, in __call__
    await self.app(scope, receive, sender)
  File "/home/haru/Projects/Major project/compliance auditor/backend/venv/lib/python3.10/site-packages/fastapi/middleware/asyncexitstack.py", line 20, in __call__
    raise e
  File "/home/haru/Projects/Major project/compliance auditor/backend/venv/lib/python3.10/site-packages/fastapi/middleware/asyncexitstack.py", line 17, in __call__
    await self.app(scope, receive, send)
  File "/home/haru/Projects/Major project/compliance auditor/backend/venv/lib/python3.10/site-packages/starlette/routing.py", line 747, in __call__
    await self.default(scope, receive, send)
  File "/home/haru/Projects/Major project/compliance auditor/backend/venv/lib/python3.10/site-packages/starlette/routing.py", line 635, in not_found
    raise HTTPException(status_code=404)
starlette.exceptions.HTTPException

During handling of the above exception, another exception occurred:

Traceback (most recent call last):
  File "/home/haru/Projects/Major project/compliance auditor/backend/venv/lib/python3.10/site-packages/starlette/middleware/errors.py", line 162, in __call__
    await self.app(scope, receive, _send)
  File "/home/haru/Projects/Major project/compliance auditor/backend/venv/lib/python3.10/site-packages/starlette/middleware/cors.py", line 83, in __call__
    await self.app(scope, receive, send)
  File "/home/haru/Projects/Major project/compliance auditor/backend/venv/lib/python3.10/site-packages/starlette/middleware/exceptions.py", line 91, in __call__
    await response(scope, receive, sender)
TypeError: 'dict' object is not callable

During handling of the above exception, another exception occurred:

Traceback (most recent call last):
  File "/home/haru/Projects/Major project/compliance auditor/backend/venv/lib/python3.10/site-packages/uvicorn/protocols/http/h11_impl.py", line 408, in run_asgi
    result = await app(  # type: ignore[func-returns-value]
  File "/home/haru/Projects/Major project/compliance auditor/backend/venv/lib/python3.10/site-packages/uvicorn/middleware/proxy_headers.py", line 84, in __call__
    return await self.app(scope, receive, send)
  File "/home/haru/Projects/Major project/compliance auditor/backend/venv/lib/python3.10/site-packages/fastapi/applications.py", line 1106, in __call__
    await super().__call__(scope, receive, send)
  File "/home/haru/Projects/Major project/compliance auditor/backend/venv/lib/python3.10/site-packages/starlette/applications.py", line 122, in __call__
    await self.middleware_stack(scope, receive, send)
  File "/home/haru/Projects/Major project/compliance auditor/backend/venv/lib/python3.10/site-packages/starlette/middleware/errors.py", line 179, in __call__
    await response(scope, receive, send)
TypeError: 'dict' object is not callable
INFO:     None:0 - "GET /logo192.png HTTP/1.1" 500 Internal Server Error
INFO:     127.0.0.1:56322 - "GET /health HTTP/1.1" 200 OK
INFO:     127.0.0.1:54874 - "GET /health HTTP/1.1" 200 OK
INFO:     127.0.0.1:54884 - "GET /health HTTP/1.1" 200 OK
ERROR:    Exception in ASGI application
Traceback (most recent call last):
  File "/home/haru/Projects/Major project/compliance auditor/backend/venv/lib/python3.10/site-packages/starlette/middleware/exceptions.py", line 68, in __call__
    await self.app(scope, receive, sender)
  File "/home/haru/Projects/Major project/compliance auditor/backend/venv/lib/python3.10/site-packages/fastapi/middleware/asyncexitstack.py", line 20, in __call__
    raise e
  File "/home/haru/Projects/Major project/compliance auditor/backend/venv/lib/python3.10/site-packages/fastapi/middleware/asyncexitstack.py", line 17, in __call__
    await self.app(scope, receive, send)
  File "/home/haru/Projects/Major project/compliance auditor/backend/venv/lib/python3.10/site-packages/starlette/routing.py", line 747, in __call__
    await self.default(scope, receive, send)
  File "/home/haru/Projects/Major project/compliance auditor/backend/venv/lib/python3.10/site-packages/starlette/routing.py", line 635, in not_found
    raise HTTPException(status_code=404)
starlette.exceptions.HTTPException

During handling of the above exception, another exception occurred:

Traceback (most recent call last):
  File "/home/haru/Projects/Major project/compliance auditor/backend/venv/lib/python3.10/site-packages/starlette/middleware/errors.py", line 162, in __call__
    await self.app(scope, receive, _send)
  File "/home/haru/Projects/Major project/compliance auditor/backend/venv/lib/python3.10/site-packages/starlette/middleware/cors.py", line 83, in __call__
    await self.app(scope, receive, send)
  File "/home/haru/Projects/Major project/compliance auditor/backend/venv/lib/python3.10/site-packages/starlette/middleware/exceptions.py", line 91, in __call__
    await response(scope, receive, sender)
TypeError: 'dict' object is not callable

During handling of the above exception, another exception occurred:

Traceback (most recent call last):
  File "/home/haru/Projects/Major project/compliance auditor/backend/venv/lib/python3.10/site-packages/uvicorn/protocols/http/h11_impl.py", line 408, in run_asgi
    result = await app(  # type: ignore[func-returns-value]
  File "/home/haru/Projects/Major project/compliance auditor/backend/venv/lib/python3.10/site-packages/uvicorn/middleware/proxy_headers.py", line 84, in __call__
    return await self.app(scope, receive, send)
  File "/home/haru/Projects/Major project/compliance auditor/backend/venv/lib/python3.10/site-packages/fastapi/applications.py", line 1106, in __call__
    await super().__call__(scope, receive, send)
  File "/home/haru/Projects/Major project/compliance auditor/backend/venv/lib/python3.10/site-packages/starlette/applications.py", line 122, in __call__
    await self.middleware_stack(scope, receive, send)
  File "/home/haru/Projects/Major project/compliance auditor/backend/venv/lib/python3.10/site-packages/starlette/middleware/errors.py", line 179, in __call__
    await response(scope, receive, send)
TypeError: 'dict' object is not callable
INFO:     None:0 - "GET /logo192.png HTTP/1.1" 500 Internal Server Error
INFO:     127.0.0.1:50206 - "OPTIONS /git-scan-detailed HTTP/1.1" 200 OK
INFO:utils.git_utils:Starting to clone repository: https://github.com/Haru65/Canvas.git
INFO:utils.git_utils:Cloning to: /tmp/tmpbqbqzic2/repo
INFO:utils.git_utils:Repository cloned successfully to: /tmp/tmpbqbqzic2/repo
INFO:     127.0.0.1:50206 - "POST /git-scan-detailed HTTP/1.1" 200 OK
INFO:     Shutting down
INFO:     Waiting for application shutdown.
INFO:     Application shutdown complete.
INFO:     Finished server process [248061]
